2025-06-03 16:46:09 +0000 - dagster - DEBUG - insumo_job - 4bd6238d-6b27-48fc-937f-d2d0a49862be - 5940 - LOGS_CAPTURED - Started capturing logs in process (pid: 5940).
2025-06-03 16:46:09 +0000 - dagster - DEBUG - insumo_job - 4bd6238d-6b27-48fc-937f-d2d0a49862be - 5940 - train_insumo - STEP_START - Started execution of step "train_insumo".
2025-06-03 16:46:09 +0000 - dagster - DEBUG - insumo_job - 4bd6238d-6b27-48fc-937f-d2d0a49862be - train_insumo - Loading file from: /opt/dagster/dagster_home/storage/4bd6238d-6b27-48fc-937f-d2d0a49862be/insumo_data/result using PickledObjectFilesystemIOManager...
2025-06-03 16:46:09 +0000 - dagster - DEBUG - insumo_job - 4bd6238d-6b27-48fc-937f-d2d0a49862be - 5940 - train_insumo - LOADED_INPUT - Loaded input "insumo_data" using input manager "io_manager", from output "result" of step "insumo_data"
2025-06-03 16:46:09 +0000 - dagster - DEBUG - insumo_job - 4bd6238d-6b27-48fc-937f-d2d0a49862be - 5940 - train_insumo - STEP_INPUT - Got input "insumo_data" of type "DataFrame". (Type check passed).
2025-06-03 16:46:09 +0000 - dagster - INFO - insumo_job - 4bd6238d-6b27-48fc-937f-d2d0a49862be - train_insumo - MLflow Tracking URI: http://mlflow:5000
2025-06-03 16:46:09 +0000 - dagster - INFO - insumo_job - 4bd6238d-6b27-48fc-937f-d2d0a49862be - train_insumo - MLflow S3 Endpoint: http://minio:9000
2025/06/03 16:46:09 INFO mlflow.tracking.fluent: Experiment with name 'insumo' does not exist. Creating a new experiment.
2025-06-03 16:46:09 +0000 - dagster - ERROR - insumo_job - 4bd6238d-6b27-48fc-937f-d2d0a49862be - 5940 - train_insumo - STEP_FAILURE - Execution of step "train_insumo" failed.

dagster._core.errors.DagsterExecutionStepExecutionError: Error occurred while executing op "train_insumo"::

KeyError: 'gasto_medio'

Stack Trace:
  File "/usr/local/lib/python3.10/site-packages/dagster/_core/execution/plan/utils.py", line 54, in op_execution_error_boundary
    yield
  File "/usr/local/lib/python3.10/site-packages/dagster/_utils/__init__.py", line 467, in iterate_with_context
    next_output = next(iterator)
  File "/usr/local/lib/python3.10/site-packages/dagster/_core/execution/plan/compute_generator.py", line 131, in _coerce_op_compute_fn_to_iterator
    result = invoke_compute_fn(
  File "/usr/local/lib/python3.10/site-packages/dagster/_core/execution/plan/compute_generator.py", line 125, in invoke_compute_fn
    return fn(context, **args_to_pass) if context_arg_provided else fn(**args_to_pass)
  File "/opt/dagster/app/cd4ml_pipeline/ops/insumo_ops.py", line 19, in train_insumo
    y = df['gasto_medio']  # ou 'media_estadual', conforme sua definição
  File "/usr/local/lib/python3.10/site-packages/pandas/core/frame.py", line 3807, in __getitem__
    indexer = self.columns.get_loc(key)
  File "/usr/local/lib/python3.10/site-packages/pandas/core/indexes/base.py", line 3804, in get_loc
    raise KeyError(key) from err

The above exception was caused by the following exception:
KeyError: 'gasto_medio'

Stack Trace:
  File "/usr/local/lib/python3.10/site-packages/pandas/core/indexes/base.py", line 3802, in get_loc
    return self._engine.get_loc(casted_key)
  File "pandas/_libs/index.pyx", line 138, in pandas._libs.index.IndexEngine.get_loc
  File "pandas/_libs/index.pyx", line 165, in pandas._libs.index.IndexEngine.get_loc
  File "pandas/_libs/hashtable_class_helper.pxi", line 5745, in pandas._libs.hashtable.PyObjectHashTable.get_item
  File "pandas/_libs/hashtable_class_helper.pxi", line 5753, in pandas._libs.hashtable.PyObjectHashTable.get_item

