2025-06-03 20:11:19 +0000 - dagster - DEBUG - saude_lavoura_job - 33d571fc-3bf4-4931-8f84-0f11368a8597 - 2463 - LOGS_CAPTURED - Started capturing logs in process (pid: 2463).
2025-06-03 20:11:19 +0000 - dagster - DEBUG - saude_lavoura_job - 33d571fc-3bf4-4931-8f84-0f11368a8597 - 2463 - train_saude_lavoura - STEP_START - Started execution of step "train_saude_lavoura".
2025-06-03 20:11:19 +0000 - dagster - DEBUG - saude_lavoura_job - 33d571fc-3bf4-4931-8f84-0f11368a8597 - train_saude_lavoura - Loading file from: /opt/dagster/dagster_home/storage/33d571fc-3bf4-4931-8f84-0f11368a8597/saude_lavoura_data/result using PickledObjectFilesystemIOManager...
2025-06-03 20:11:19 +0000 - dagster - DEBUG - saude_lavoura_job - 33d571fc-3bf4-4931-8f84-0f11368a8597 - 2463 - train_saude_lavoura - LOADED_INPUT - Loaded input "df" using input manager "io_manager", from output "result" of step "saude_lavoura_data"
2025-06-03 20:11:19 +0000 - dagster - DEBUG - saude_lavoura_job - 33d571fc-3bf4-4931-8f84-0f11368a8597 - 2463 - train_saude_lavoura - STEP_INPUT - Got input "df" of type "DataFrame". (Type check passed).
2025-06-03 20:11:19 +0000 - dagster - INFO - saude_lavoura_job - 33d571fc-3bf4-4931-8f84-0f11368a8597 - train_saude_lavoura - MLflow Tracking URI: http://mlflow:5000
2025-06-03 20:11:19 +0000 - dagster - INFO - saude_lavoura_job - 33d571fc-3bf4-4931-8f84-0f11368a8597 - train_saude_lavoura - MLflow S3 Endpoint: http://minio:9000
2025/06/03 20:11:20 INFO mlflow.tracking.fluent: Experiment with name 'saude_lavoura' does not exist. Creating a new experiment.
2025-06-03 20:11:20 +0000 - dagster - ERROR - saude_lavoura_job - 33d571fc-3bf4-4931-8f84-0f11368a8597 - 2463 - train_saude_lavoura - STEP_FAILURE - Execution of step "train_saude_lavoura" failed.

dagster._core.errors.DagsterExecutionStepExecutionError: Error occurred while executing op "train_saude_lavoura"::

KeyError: 'media_estadual'

Stack Trace:
  File "/usr/local/lib/python3.10/site-packages/dagster/_core/execution/plan/utils.py", line 54, in op_execution_error_boundary
    yield
  File "/usr/local/lib/python3.10/site-packages/dagster/_utils/__init__.py", line 467, in iterate_with_context
    next_output = next(iterator)
  File "/usr/local/lib/python3.10/site-packages/dagster/_core/execution/plan/compute_generator.py", line 131, in _coerce_op_compute_fn_to_iterator
    result = invoke_compute_fn(
  File "/usr/local/lib/python3.10/site-packages/dagster/_core/execution/plan/compute_generator.py", line 125, in invoke_compute_fn
    return fn(context, **args_to_pass) if context_arg_provided else fn(**args_to_pass)
  File "/opt/dagster/app/cd4ml_pipeline/ops/saude_lavoura_ops.py", line 15, in train_saude_lavoura
    y = df['media_estadual']
  File "/usr/local/lib/python3.10/site-packages/pandas/core/frame.py", line 3807, in __getitem__
    indexer = self.columns.get_loc(key)
  File "/usr/local/lib/python3.10/site-packages/pandas/core/indexes/base.py", line 3804, in get_loc
    raise KeyError(key) from err

The above exception was caused by the following exception:
KeyError: 'media_estadual'

Stack Trace:
  File "/usr/local/lib/python3.10/site-packages/pandas/core/indexes/base.py", line 3802, in get_loc
    return self._engine.get_loc(casted_key)
  File "pandas/_libs/index.pyx", line 138, in pandas._libs.index.IndexEngine.get_loc
  File "pandas/_libs/index.pyx", line 165, in pandas._libs.index.IndexEngine.get_loc
  File "pandas/_libs/hashtable_class_helper.pxi", line 5745, in pandas._libs.hashtable.PyObjectHashTable.get_item
  File "pandas/_libs/hashtable_class_helper.pxi", line 5753, in pandas._libs.hashtable.PyObjectHashTable.get_item

